{"timestamp": "2024-07-22 20:42:43,596", "level": "INFO", "message": "This is an informational message", "service": "my_python_app", "environment": "development"}

{"timestamp": "2024-07-22 20:42:43,596", "level": "WARNING", "message": "A warning occurred", "service": "my_python_app", "environment": "development"}

{"timestamp": "2024-07-22 20:42:43,596", "level": "ERROR", "message": "Error message with traceback", "service": "my_python_app", "environment": "development", "exception": {"type": "ValueError", "message": "An error occurred", "traceback": "Traceback (most recent call last):\n  File \"/home/azureuser/python-sample/log2.py\", line 40, in <module>\n    raise ValueError(\"An error occurred\")\nValueError: An error occurred\n"}}

{"timestamp": "2024-07-22 20:43:31,140", "level": "INFO", "message": "This is an informational message", "service": "my_python_app", "environment": "development"}

{"timestamp": "2024-07-22 20:43:31,140", "level": "WARNING", "message": "A warning occurred", "service": "my_python_app", "environment": "development"}

{"timestamp": "2024-07-22 20:43:31,140", "level": "ERROR", "message": "Caught an error", "service": "my_python_app", "environment": "development", "exception": {"type": "ValueError", "message": "This is a sample error for logging", "traceback": "Traceback (most recent call last):\n  File \"/home/azureuser/python-sample/log2.py\", line 43, in <module>\n    raise ValueError(\"This is a sample error for logging\")\nValueError: This is a sample error for logging\n"}}

{"timestamp": "2024-07-22 20:43:31,144", "level": "INFO", "message": "End of logging example", "service": "my_python_app", "environment": "development"}

{"timestamp": "2024-07-22 20:55:31,017", "level": "INFO", "message": "This is an informational message", "service": "my_python_app", "environment": "development"}

{"timestamp": "2024-07-22 20:55:31,018", "level": "WARNING", "message": "A warning occurred", "service": "my_python_app", "environment": "development"}

{"timestamp": "2024-07-22 20:55:31,018", "level": "ERROR", "message": "Caught an error", "service": "my_python_app", "environment": "development", "exception": {"type": "ValueError", "message": "This is a sample error for logging", "traceback": "Traceback (most recent call last):\n  File \"/home/azureuser/./python-sample/log2.py\", line 43, in <module>\n    raise ValueError(\"This is a sample error for logging\")\nValueError: This is a sample error for logging\n"}}

{"timestamp": "2024-07-22 20:55:31,022", "level": "INFO", "message": "End of logging example", "service": "my_python_app", "environment": "development"}

{"timestamp": "2024-07-22 20:55:00,000", "level": "INFO", "message": "Test log entry", "service": "my_python_app", "environment": "development"}
{"timestamp": "2024-07-22 20:59:44,915", "level": "INFO", "message": "This is an informational message", "service": "my_python_app", "environment": "development"}

{"timestamp": "2024-07-22 20:59:44,915", "level": "WARNING", "message": "A warning occurred", "service": "my_python_app", "environment": "development"}

{"timestamp": "2024-07-22 20:59:44,915", "level": "ERROR", "message": "Caught an error", "service": "my_python_app", "environment": "development", "exception": {"type": "ValueError", "message": "This is a sample error for logging", "traceback": "Traceback (most recent call last):\n  File \"/home/azureuser/./python-sample/log2.py\", line 43, in <module>\n    raise ValueError(\"This is a sample error for logging\")\nValueError: This is a sample error for logging\n"}}

{"timestamp": "2024-07-22 20:59:44,919", "level": "INFO", "message": "End of logging example", "service": "my_python_app", "environment": "development"}

{"timestamp": "2024-07-22 21:00:33,228", "level": "INFO", "message": "This is an informational message", "service": "my_python_app", "environment": "development"}

{"timestamp": "2024-07-22 21:00:33,228", "level": "WARNING", "message": "A warning occurred", "service": "my_python_app", "environment": "development"}

{"timestamp": "2024-07-22 21:00:33,228", "level": "ERROR", "message": "Caught an error: This is sample error number 1 for logging", "service": "my_python_app", "environment": "development", "exception": {"type": "ValueError", "message": "This is sample error number 1 for logging", "traceback": "Traceback (most recent call last):\n  File \"/home/azureuser/./python-sample/log2.py\", line 44, in <module>\n    raise ValueError(f\"This is sample error number {i + 1} for logging\")\nValueError: This is sample error number 1 for logging\n"}}

{"timestamp": "2024-07-22 21:00:33,233", "level": "ERROR", "message": "Caught an error: This is sample error number 2 for logging", "service": "my_python_app", "environment": "development", "exception": {"type": "ValueError", "message": "This is sample error number 2 for logging", "traceback": "Traceback (most recent call last):\n  File \"/home/azureuser/./python-sample/log2.py\", line 44, in <module>\n    raise ValueError(f\"This is sample error number {i + 1} for logging\")\nValueError: This is sample error number 2 for logging\n"}}

{"timestamp": "2024-07-22 21:00:33,234", "level": "ERROR", "message": "Caught an error: This is sample error number 3 for logging", "service": "my_python_app", "environment": "development", "exception": {"type": "ValueError", "message": "This is sample error number 3 for logging", "traceback": "Traceback (most recent call last):\n  File \"/home/azureuser/./python-sample/log2.py\", line 44, in <module>\n    raise ValueError(f\"This is sample error number {i + 1} for logging\")\nValueError: This is sample error number 3 for logging\n"}}

{"timestamp": "2024-07-22 21:00:33,234", "level": "ERROR", "message": "Caught an error: This is sample error number 4 for logging", "service": "my_python_app", "environment": "development", "exception": {"type": "ValueError", "message": "This is sample error number 4 for logging", "traceback": "Traceback (most recent call last):\n  File \"/home/azureuser/./python-sample/log2.py\", line 44, in <module>\n    raise ValueError(f\"This is sample error number {i + 1} for logging\")\nValueError: This is sample error number 4 for logging\n"}}

{"timestamp": "2024-07-22 21:00:33,234", "level": "ERROR", "message": "Caught an error: This is sample error number 5 for logging", "service": "my_python_app", "environment": "development", "exception": {"type": "ValueError", "message": "This is sample error number 5 for logging", "traceback": "Traceback (most recent call last):\n  File \"/home/azureuser/./python-sample/log2.py\", line 44, in <module>\n    raise ValueError(f\"This is sample error number {i + 1} for logging\")\nValueError: This is sample error number 5 for logging\n"}}

{"timestamp": "2024-07-22 21:00:33,234", "level": "ERROR", "message": "Caught an error: This is sample error number 6 for logging", "service": "my_python_app", "environment": "development", "exception": {"type": "ValueError", "message": "This is sample error number 6 for logging", "traceback": "Traceback (most recent call last):\n  File \"/home/azureuser/./python-sample/log2.py\", line 44, in <module>\n    raise ValueError(f\"This is sample error number {i + 1} for logging\")\nValueError: This is sample error number 6 for logging\n"}}

{"timestamp": "2024-07-22 21:00:33,235", "level": "ERROR", "message": "Caught an error: This is sample error number 7 for logging", "service": "my_python_app", "environment": "development", "exception": {"type": "ValueError", "message": "This is sample error number 7 for logging", "traceback": "Traceback (most recent call last):\n  File \"/home/azureuser/./python-sample/log2.py\", line 44, in <module>\n    raise ValueError(f\"This is sample error number {i + 1} for logging\")\nValueError: This is sample error number 7 for logging\n"}}

{"timestamp": "2024-07-22 21:00:33,235", "level": "ERROR", "message": "Caught an error: This is sample error number 8 for logging", "service": "my_python_app", "environment": "development", "exception": {"type": "ValueError", "message": "This is sample error number 8 for logging", "traceback": "Traceback (most recent call last):\n  File \"/home/azureuser/./python-sample/log2.py\", line 44, in <module>\n    raise ValueError(f\"This is sample error number {i + 1} for logging\")\nValueError: This is sample error number 8 for logging\n"}}

{"timestamp": "2024-07-22 21:00:33,235", "level": "ERROR", "message": "Caught an error: This is sample error number 9 for logging", "service": "my_python_app", "environment": "development", "exception": {"type": "ValueError", "message": "This is sample error number 9 for logging", "traceback": "Traceback (most recent call last):\n  File \"/home/azureuser/./python-sample/log2.py\", line 44, in <module>\n    raise ValueError(f\"This is sample error number {i + 1} for logging\")\nValueError: This is sample error number 9 for logging\n"}}

{"timestamp": "2024-07-22 21:00:33,235", "level": "ERROR", "message": "Caught an error: This is sample error number 10 for logging", "service": "my_python_app", "environment": "development", "exception": {"type": "ValueError", "message": "This is sample error number 10 for logging", "traceback": "Traceback (most recent call last):\n  File \"/home/azureuser/./python-sample/log2.py\", line 44, in <module>\n    raise ValueError(f\"This is sample error number {i + 1} for logging\")\nValueError: This is sample error number 10 for logging\n"}}

{"timestamp": "2024-07-22 21:00:33,236", "level": "ERROR", "message": "Caught an error: This is sample error number 11 for logging", "service": "my_python_app", "environment": "development", "exception": {"type": "ValueError", "message": "This is sample error number 11 for logging", "traceback": "Traceback (most recent call last):\n  File \"/home/azureuser/./python-sample/log2.py\", line 44, in <module>\n    raise ValueError(f\"This is sample error number {i + 1} for logging\")\nValueError: This is sample error number 11 for logging\n"}}

{"timestamp": "2024-07-22 21:00:33,236", "level": "ERROR", "message": "Caught an error: This is sample error number 12 for logging", "service": "my_python_app", "environment": "development", "exception": {"type": "ValueError", "message": "This is sample error number 12 for logging", "traceback": "Traceback (most recent call last):\n  File \"/home/azureuser/./python-sample/log2.py\", line 44, in <module>\n    raise ValueError(f\"This is sample error number {i + 1} for logging\")\nValueError: This is sample error number 12 for logging\n"}}

{"timestamp": "2024-07-22 21:00:33,236", "level": "ERROR", "message": "Caught an error: This is sample error number 13 for logging", "service": "my_python_app", "environment": "development", "exception": {"type": "ValueError", "message": "This is sample error number 13 for logging", "traceback": "Traceback (most recent call last):\n  File \"/home/azureuser/./python-sample/log2.py\", line 44, in <module>\n    raise ValueError(f\"This is sample error number {i + 1} for logging\")\nValueError: This is sample error number 13 for logging\n"}}

{"timestamp": "2024-07-22 21:00:33,237", "level": "ERROR", "message": "Caught an error: This is sample error number 14 for logging", "service": "my_python_app", "environment": "development", "exception": {"type": "ValueError", "message": "This is sample error number 14 for logging", "traceback": "Traceback (most recent call last):\n  File \"/home/azureuser/./python-sample/log2.py\", line 44, in <module>\n    raise ValueError(f\"This is sample error number {i + 1} for logging\")\nValueError: This is sample error number 14 for logging\n"}}

{"timestamp": "2024-07-22 21:00:33,237", "level": "ERROR", "message": "Caught an error: This is sample error number 15 for logging", "service": "my_python_app", "environment": "development", "exception": {"type": "ValueError", "message": "This is sample error number 15 for logging", "traceback": "Traceback (most recent call last):\n  File \"/home/azureuser/./python-sample/log2.py\", line 44, in <module>\n    raise ValueError(f\"This is sample error number {i + 1} for logging\")\nValueError: This is sample error number 15 for logging\n"}}

{"timestamp": "2024-07-22 21:00:33,237", "level": "ERROR", "message": "Caught an error: This is sample error number 16 for logging", "service": "my_python_app", "environment": "development", "exception": {"type": "ValueError", "message": "This is sample error number 16 for logging", "traceback": "Traceback (most recent call last):\n  File \"/home/azureuser/./python-sample/log2.py\", line 44, in <module>\n    raise ValueError(f\"This is sample error number {i + 1} for logging\")\nValueError: This is sample error number 16 for logging\n"}}

{"timestamp": "2024-07-22 21:00:33,237", "level": "ERROR", "message": "Caught an error: This is sample error number 17 for logging", "service": "my_python_app", "environment": "development", "exception": {"type": "ValueError", "message": "This is sample error number 17 for logging", "traceback": "Traceback (most recent call last):\n  File \"/home/azureuser/./python-sample/log2.py\", line 44, in <module>\n    raise ValueError(f\"This is sample error number {i + 1} for logging\")\nValueError: This is sample error number 17 for logging\n"}}

{"timestamp": "2024-07-22 21:00:33,238", "level": "ERROR", "message": "Caught an error: This is sample error number 18 for logging", "service": "my_python_app", "environment": "development", "exception": {"type": "ValueError", "message": "This is sample error number 18 for logging", "traceback": "Traceback (most recent call last):\n  File \"/home/azureuser/./python-sample/log2.py\", line 44, in <module>\n    raise ValueError(f\"This is sample error number {i + 1} for logging\")\nValueError: This is sample error number 18 for logging\n"}}

{"timestamp": "2024-07-22 21:00:33,238", "level": "ERROR", "message": "Caught an error: This is sample error number 19 for logging", "service": "my_python_app", "environment": "development", "exception": {"type": "ValueError", "message": "This is sample error number 19 for logging", "traceback": "Traceback (most recent call last):\n  File \"/home/azureuser/./python-sample/log2.py\", line 44, in <module>\n    raise ValueError(f\"This is sample error number {i + 1} for logging\")\nValueError: This is sample error number 19 for logging\n"}}

{"timestamp": "2024-07-22 21:00:33,238", "level": "ERROR", "message": "Caught an error: This is sample error number 20 for logging", "service": "my_python_app", "environment": "development", "exception": {"type": "ValueError", "message": "This is sample error number 20 for logging", "traceback": "Traceback (most recent call last):\n  File \"/home/azureuser/./python-sample/log2.py\", line 44, in <module>\n    raise ValueError(f\"This is sample error number {i + 1} for logging\")\nValueError: This is sample error number 20 for logging\n"}}

{"timestamp": "2024-07-22 21:00:33,239", "level": "INFO", "message": "End of logging example", "service": "my_python_app", "environment": "development"}

{"timestamp": "2024-07-23 11:46:30,698", "level": "INFO", "message": "This is an informational message", "service": "my_python_app", "environment": "development"}

{"timestamp": "2024-07-23 11:46:30,698", "level": "WARNING", "message": "A warning occurred", "service": "my_python_app", "environment": "development"}

{"timestamp": "2024-07-23 11:46:30,698", "level": "ERROR", "message": "Caught an error: This is sample error number 1 for logging", "service": "my_python_app", "environment": "development", "exception": {"type": "ValueError", "message": "This is sample error number 1 for logging", "traceback": "Traceback (most recent call last):\n  File \"/home/azureuser/./python-sample/log2.py\", line 44, in <module>\n    raise ValueError(f\"This is sample error number {i + 1} for logging\")\nValueError: This is sample error number 1 for logging\n"}}

{"timestamp": "2024-07-23 11:46:30,702", "level": "ERROR", "message": "Caught an error: This is sample error number 2 for logging", "service": "my_python_app", "environment": "development", "exception": {"type": "ValueError", "message": "This is sample error number 2 for logging", "traceback": "Traceback (most recent call last):\n  File \"/home/azureuser/./python-sample/log2.py\", line 44, in <module>\n    raise ValueError(f\"This is sample error number {i + 1} for logging\")\nValueError: This is sample error number 2 for logging\n"}}

{"timestamp": "2024-07-23 11:46:30,703", "level": "ERROR", "message": "Caught an error: This is sample error number 3 for logging", "service": "my_python_app", "environment": "development", "exception": {"type": "ValueError", "message": "This is sample error number 3 for logging", "traceback": "Traceback (most recent call last):\n  File \"/home/azureuser/./python-sample/log2.py\", line 44, in <module>\n    raise ValueError(f\"This is sample error number {i + 1} for logging\")\nValueError: This is sample error number 3 for logging\n"}}

{"timestamp": "2024-07-23 11:46:30,703", "level": "ERROR", "message": "Caught an error: This is sample error number 4 for logging", "service": "my_python_app", "environment": "development", "exception": {"type": "ValueError", "message": "This is sample error number 4 for logging", "traceback": "Traceback (most recent call last):\n  File \"/home/azureuser/./python-sample/log2.py\", line 44, in <module>\n    raise ValueError(f\"This is sample error number {i + 1} for logging\")\nValueError: This is sample error number 4 for logging\n"}}

{"timestamp": "2024-07-23 11:46:30,703", "level": "ERROR", "message": "Caught an error: This is sample error number 5 for logging", "service": "my_python_app", "environment": "development", "exception": {"type": "ValueError", "message": "This is sample error number 5 for logging", "traceback": "Traceback (most recent call last):\n  File \"/home/azureuser/./python-sample/log2.py\", line 44, in <module>\n    raise ValueError(f\"This is sample error number {i + 1} for logging\")\nValueError: This is sample error number 5 for logging\n"}}

{"timestamp": "2024-07-23 11:46:30,703", "level": "ERROR", "message": "Caught an error: This is sample error number 6 for logging", "service": "my_python_app", "environment": "development", "exception": {"type": "ValueError", "message": "This is sample error number 6 for logging", "traceback": "Traceback (most recent call last):\n  File \"/home/azureuser/./python-sample/log2.py\", line 44, in <module>\n    raise ValueError(f\"This is sample error number {i + 1} for logging\")\nValueError: This is sample error number 6 for logging\n"}}

{"timestamp": "2024-07-23 11:46:30,704", "level": "ERROR", "message": "Caught an error: This is sample error number 7 for logging", "service": "my_python_app", "environment": "development", "exception": {"type": "ValueError", "message": "This is sample error number 7 for logging", "traceback": "Traceback (most recent call last):\n  File \"/home/azureuser/./python-sample/log2.py\", line 44, in <module>\n    raise ValueError(f\"This is sample error number {i + 1} for logging\")\nValueError: This is sample error number 7 for logging\n"}}

{"timestamp": "2024-07-23 11:46:30,704", "level": "ERROR", "message": "Caught an error: This is sample error number 8 for logging", "service": "my_python_app", "environment": "development", "exception": {"type": "ValueError", "message": "This is sample error number 8 for logging", "traceback": "Traceback (most recent call last):\n  File \"/home/azureuser/./python-sample/log2.py\", line 44, in <module>\n    raise ValueError(f\"This is sample error number {i + 1} for logging\")\nValueError: This is sample error number 8 for logging\n"}}

{"timestamp": "2024-07-23 11:46:30,704", "level": "ERROR", "message": "Caught an error: This is sample error number 9 for logging", "service": "my_python_app", "environment": "development", "exception": {"type": "ValueError", "message": "This is sample error number 9 for logging", "traceback": "Traceback (most recent call last):\n  File \"/home/azureuser/./python-sample/log2.py\", line 44, in <module>\n    raise ValueError(f\"This is sample error number {i + 1} for logging\")\nValueError: This is sample error number 9 for logging\n"}}

{"timestamp": "2024-07-23 11:46:30,704", "level": "ERROR", "message": "Caught an error: This is sample error number 10 for logging", "service": "my_python_app", "environment": "development", "exception": {"type": "ValueError", "message": "This is sample error number 10 for logging", "traceback": "Traceback (most recent call last):\n  File \"/home/azureuser/./python-sample/log2.py\", line 44, in <module>\n    raise ValueError(f\"This is sample error number {i + 1} for logging\")\nValueError: This is sample error number 10 for logging\n"}}

{"timestamp": "2024-07-23 11:46:30,704", "level": "ERROR", "message": "Caught an error: This is sample error number 11 for logging", "service": "my_python_app", "environment": "development", "exception": {"type": "ValueError", "message": "This is sample error number 11 for logging", "traceback": "Traceback (most recent call last):\n  File \"/home/azureuser/./python-sample/log2.py\", line 44, in <module>\n    raise ValueError(f\"This is sample error number {i + 1} for logging\")\nValueError: This is sample error number 11 for logging\n"}}

{"timestamp": "2024-07-23 11:46:30,705", "level": "ERROR", "message": "Caught an error: This is sample error number 12 for logging", "service": "my_python_app", "environment": "development", "exception": {"type": "ValueError", "message": "This is sample error number 12 for logging", "traceback": "Traceback (most recent call last):\n  File \"/home/azureuser/./python-sample/log2.py\", line 44, in <module>\n    raise ValueError(f\"This is sample error number {i + 1} for logging\")\nValueError: This is sample error number 12 for logging\n"}}

{"timestamp": "2024-07-23 11:46:30,705", "level": "ERROR", "message": "Caught an error: This is sample error number 13 for logging", "service": "my_python_app", "environment": "development", "exception": {"type": "ValueError", "message": "This is sample error number 13 for logging", "traceback": "Traceback (most recent call last):\n  File \"/home/azureuser/./python-sample/log2.py\", line 44, in <module>\n    raise ValueError(f\"This is sample error number {i + 1} for logging\")\nValueError: This is sample error number 13 for logging\n"}}

{"timestamp": "2024-07-23 11:46:30,705", "level": "ERROR", "message": "Caught an error: This is sample error number 14 for logging", "service": "my_python_app", "environment": "development", "exception": {"type": "ValueError", "message": "This is sample error number 14 for logging", "traceback": "Traceback (most recent call last):\n  File \"/home/azureuser/./python-sample/log2.py\", line 44, in <module>\n    raise ValueError(f\"This is sample error number {i + 1} for logging\")\nValueError: This is sample error number 14 for logging\n"}}

{"timestamp": "2024-07-23 11:46:30,705", "level": "ERROR", "message": "Caught an error: This is sample error number 15 for logging", "service": "my_python_app", "environment": "development", "exception": {"type": "ValueError", "message": "This is sample error number 15 for logging", "traceback": "Traceback (most recent call last):\n  File \"/home/azureuser/./python-sample/log2.py\", line 44, in <module>\n    raise ValueError(f\"This is sample error number {i + 1} for logging\")\nValueError: This is sample error number 15 for logging\n"}}

{"timestamp": "2024-07-23 11:46:30,706", "level": "ERROR", "message": "Caught an error: This is sample error number 16 for logging", "service": "my_python_app", "environment": "development", "exception": {"type": "ValueError", "message": "This is sample error number 16 for logging", "traceback": "Traceback (most recent call last):\n  File \"/home/azureuser/./python-sample/log2.py\", line 44, in <module>\n    raise ValueError(f\"This is sample error number {i + 1} for logging\")\nValueError: This is sample error number 16 for logging\n"}}

{"timestamp": "2024-07-23 11:46:30,706", "level": "ERROR", "message": "Caught an error: This is sample error number 17 for logging", "service": "my_python_app", "environment": "development", "exception": {"type": "ValueError", "message": "This is sample error number 17 for logging", "traceback": "Traceback (most recent call last):\n  File \"/home/azureuser/./python-sample/log2.py\", line 44, in <module>\n    raise ValueError(f\"This is sample error number {i + 1} for logging\")\nValueError: This is sample error number 17 for logging\n"}}

{"timestamp": "2024-07-23 11:46:30,706", "level": "ERROR", "message": "Caught an error: This is sample error number 18 for logging", "service": "my_python_app", "environment": "development", "exception": {"type": "ValueError", "message": "This is sample error number 18 for logging", "traceback": "Traceback (most recent call last):\n  File \"/home/azureuser/./python-sample/log2.py\", line 44, in <module>\n    raise ValueError(f\"This is sample error number {i + 1} for logging\")\nValueError: This is sample error number 18 for logging\n"}}

{"timestamp": "2024-07-23 11:46:30,706", "level": "ERROR", "message": "Caught an error: This is sample error number 19 for logging", "service": "my_python_app", "environment": "development", "exception": {"type": "ValueError", "message": "This is sample error number 19 for logging", "traceback": "Traceback (most recent call last):\n  File \"/home/azureuser/./python-sample/log2.py\", line 44, in <module>\n    raise ValueError(f\"This is sample error number {i + 1} for logging\")\nValueError: This is sample error number 19 for logging\n"}}

{"timestamp": "2024-07-23 11:46:30,706", "level": "ERROR", "message": "Caught an error: This is sample error number 20 for logging", "service": "my_python_app", "environment": "development", "exception": {"type": "ValueError", "message": "This is sample error number 20 for logging", "traceback": "Traceback (most recent call last):\n  File \"/home/azureuser/./python-sample/log2.py\", line 44, in <module>\n    raise ValueError(f\"This is sample error number {i + 1} for logging\")\nValueError: This is sample error number 20 for logging\n"}}

{"timestamp": "2024-07-23 11:46:30,707", "level": "INFO", "message": "End of logging example", "service": "my_python_app", "environment": "development"}

{"timestamp": "2024-07-23 11:46:55,011", "level": "INFO", "message": "This is an informational message", "service": "my_python_app", "environment": "development"}

{"timestamp": "2024-07-23 11:46:55,011", "level": "WARNING", "message": "A warning occurred", "service": "my_python_app", "environment": "development"}

{"timestamp": "2024-07-23 11:46:55,011", "level": "ERROR", "message": "Caught an error: This is sample error number 1 for logging", "service": "my_python_app", "environment": "development", "exception": {"type": "ValueError", "message": "This is sample error number 1 for logging", "traceback": "Traceback (most recent call last):\n  File \"/home/azureuser/./python-sample/log2.py\", line 44, in <module>\n    raise ValueError(f\"This is sample error number {i + 1} for logging\")\nValueError: This is sample error number 1 for logging\n"}}

{"timestamp": "2024-07-23 11:46:55,014", "level": "ERROR", "message": "Caught an error: This is sample error number 2 for logging", "service": "my_python_app", "environment": "development", "exception": {"type": "ValueError", "message": "This is sample error number 2 for logging", "traceback": "Traceback (most recent call last):\n  File \"/home/azureuser/./python-sample/log2.py\", line 44, in <module>\n    raise ValueError(f\"This is sample error number {i + 1} for logging\")\nValueError: This is sample error number 2 for logging\n"}}

{"timestamp": "2024-07-23 11:46:55,015", "level": "ERROR", "message": "Caught an error: This is sample error number 3 for logging", "service": "my_python_app", "environment": "development", "exception": {"type": "ValueError", "message": "This is sample error number 3 for logging", "traceback": "Traceback (most recent call last):\n  File \"/home/azureuser/./python-sample/log2.py\", line 44, in <module>\n    raise ValueError(f\"This is sample error number {i + 1} for logging\")\nValueError: This is sample error number 3 for logging\n"}}

{"timestamp": "2024-07-23 11:46:55,015", "level": "ERROR", "message": "Caught an error: This is sample error number 4 for logging", "service": "my_python_app", "environment": "development", "exception": {"type": "ValueError", "message": "This is sample error number 4 for logging", "traceback": "Traceback (most recent call last):\n  File \"/home/azureuser/./python-sample/log2.py\", line 44, in <module>\n    raise ValueError(f\"This is sample error number {i + 1} for logging\")\nValueError: This is sample error number 4 for logging\n"}}

{"timestamp": "2024-07-23 11:46:55,015", "level": "ERROR", "message": "Caught an error: This is sample error number 5 for logging", "service": "my_python_app", "environment": "development", "exception": {"type": "ValueError", "message": "This is sample error number 5 for logging", "traceback": "Traceback (most recent call last):\n  File \"/home/azureuser/./python-sample/log2.py\", line 44, in <module>\n    raise ValueError(f\"This is sample error number {i + 1} for logging\")\nValueError: This is sample error number 5 for logging\n"}}

{"timestamp": "2024-07-23 11:46:55,016", "level": "ERROR", "message": "Caught an error: This is sample error number 6 for logging", "service": "my_python_app", "environment": "development", "exception": {"type": "ValueError", "message": "This is sample error number 6 for logging", "traceback": "Traceback (most recent call last):\n  File \"/home/azureuser/./python-sample/log2.py\", line 44, in <module>\n    raise ValueError(f\"This is sample error number {i + 1} for logging\")\nValueError: This is sample error number 6 for logging\n"}}

{"timestamp": "2024-07-23 11:46:55,016", "level": "ERROR", "message": "Caught an error: This is sample error number 7 for logging", "service": "my_python_app", "environment": "development", "exception": {"type": "ValueError", "message": "This is sample error number 7 for logging", "traceback": "Traceback (most recent call last):\n  File \"/home/azureuser/./python-sample/log2.py\", line 44, in <module>\n    raise ValueError(f\"This is sample error number {i + 1} for logging\")\nValueError: This is sample error number 7 for logging\n"}}

{"timestamp": "2024-07-23 11:46:55,016", "level": "ERROR", "message": "Caught an error: This is sample error number 8 for logging", "service": "my_python_app", "environment": "development", "exception": {"type": "ValueError", "message": "This is sample error number 8 for logging", "traceback": "Traceback (most recent call last):\n  File \"/home/azureuser/./python-sample/log2.py\", line 44, in <module>\n    raise ValueError(f\"This is sample error number {i + 1} for logging\")\nValueError: This is sample error number 8 for logging\n"}}

{"timestamp": "2024-07-23 11:46:55,016", "level": "ERROR", "message": "Caught an error: This is sample error number 9 for logging", "service": "my_python_app", "environment": "development", "exception": {"type": "ValueError", "message": "This is sample error number 9 for logging", "traceback": "Traceback (most recent call last):\n  File \"/home/azureuser/./python-sample/log2.py\", line 44, in <module>\n    raise ValueError(f\"This is sample error number {i + 1} for logging\")\nValueError: This is sample error number 9 for logging\n"}}

{"timestamp": "2024-07-23 11:46:55,016", "level": "ERROR", "message": "Caught an error: This is sample error number 10 for logging", "service": "my_python_app", "environment": "development", "exception": {"type": "ValueError", "message": "This is sample error number 10 for logging", "traceback": "Traceback (most recent call last):\n  File \"/home/azureuser/./python-sample/log2.py\", line 44, in <module>\n    raise ValueError(f\"This is sample error number {i + 1} for logging\")\nValueError: This is sample error number 10 for logging\n"}}

{"timestamp": "2024-07-23 11:46:55,017", "level": "ERROR", "message": "Caught an error: This is sample error number 11 for logging", "service": "my_python_app", "environment": "development", "exception": {"type": "ValueError", "message": "This is sample error number 11 for logging", "traceback": "Traceback (most recent call last):\n  File \"/home/azureuser/./python-sample/log2.py\", line 44, in <module>\n    raise ValueError(f\"This is sample error number {i + 1} for logging\")\nValueError: This is sample error number 11 for logging\n"}}

{"timestamp": "2024-07-23 11:46:55,017", "level": "ERROR", "message": "Caught an error: This is sample error number 12 for logging", "service": "my_python_app", "environment": "development", "exception": {"type": "ValueError", "message": "This is sample error number 12 for logging", "traceback": "Traceback (most recent call last):\n  File \"/home/azureuser/./python-sample/log2.py\", line 44, in <module>\n    raise ValueError(f\"This is sample error number {i + 1} for logging\")\nValueError: This is sample error number 12 for logging\n"}}

{"timestamp": "2024-07-23 11:46:55,017", "level": "ERROR", "message": "Caught an error: This is sample error number 13 for logging", "service": "my_python_app", "environment": "development", "exception": {"type": "ValueError", "message": "This is sample error number 13 for logging", "traceback": "Traceback (most recent call last):\n  File \"/home/azureuser/./python-sample/log2.py\", line 44, in <module>\n    raise ValueError(f\"This is sample error number {i + 1} for logging\")\nValueError: This is sample error number 13 for logging\n"}}

{"timestamp": "2024-07-23 11:46:55,017", "level": "ERROR", "message": "Caught an error: This is sample error number 14 for logging", "service": "my_python_app", "environment": "development", "exception": {"type": "ValueError", "message": "This is sample error number 14 for logging", "traceback": "Traceback (most recent call last):\n  File \"/home/azureuser/./python-sample/log2.py\", line 44, in <module>\n    raise ValueError(f\"This is sample error number {i + 1} for logging\")\nValueError: This is sample error number 14 for logging\n"}}

{"timestamp": "2024-07-23 11:46:55,017", "level": "ERROR", "message": "Caught an error: This is sample error number 15 for logging", "service": "my_python_app", "environment": "development", "exception": {"type": "ValueError", "message": "This is sample error number 15 for logging", "traceback": "Traceback (most recent call last):\n  File \"/home/azureuser/./python-sample/log2.py\", line 44, in <module>\n    raise ValueError(f\"This is sample error number {i + 1} for logging\")\nValueError: This is sample error number 15 for logging\n"}}

{"timestamp": "2024-07-23 11:46:55,018", "level": "ERROR", "message": "Caught an error: This is sample error number 16 for logging", "service": "my_python_app", "environment": "development", "exception": {"type": "ValueError", "message": "This is sample error number 16 for logging", "traceback": "Traceback (most recent call last):\n  File \"/home/azureuser/./python-sample/log2.py\", line 44, in <module>\n    raise ValueError(f\"This is sample error number {i + 1} for logging\")\nValueError: This is sample error number 16 for logging\n"}}

{"timestamp": "2024-07-23 11:46:55,018", "level": "ERROR", "message": "Caught an error: This is sample error number 17 for logging", "service": "my_python_app", "environment": "development", "exception": {"type": "ValueError", "message": "This is sample error number 17 for logging", "traceback": "Traceback (most recent call last):\n  File \"/home/azureuser/./python-sample/log2.py\", line 44, in <module>\n    raise ValueError(f\"This is sample error number {i + 1} for logging\")\nValueError: This is sample error number 17 for logging\n"}}

{"timestamp": "2024-07-23 11:46:55,018", "level": "ERROR", "message": "Caught an error: This is sample error number 18 for logging", "service": "my_python_app", "environment": "development", "exception": {"type": "ValueError", "message": "This is sample error number 18 for logging", "traceback": "Traceback (most recent call last):\n  File \"/home/azureuser/./python-sample/log2.py\", line 44, in <module>\n    raise ValueError(f\"This is sample error number {i + 1} for logging\")\nValueError: This is sample error number 18 for logging\n"}}

{"timestamp": "2024-07-23 11:46:55,018", "level": "ERROR", "message": "Caught an error: This is sample error number 19 for logging", "service": "my_python_app", "environment": "development", "exception": {"type": "ValueError", "message": "This is sample error number 19 for logging", "traceback": "Traceback (most recent call last):\n  File \"/home/azureuser/./python-sample/log2.py\", line 44, in <module>\n    raise ValueError(f\"This is sample error number {i + 1} for logging\")\nValueError: This is sample error number 19 for logging\n"}}

{"timestamp": "2024-07-23 11:46:55,018", "level": "ERROR", "message": "Caught an error: This is sample error number 20 for logging", "service": "my_python_app", "environment": "development", "exception": {"type": "ValueError", "message": "This is sample error number 20 for logging", "traceback": "Traceback (most recent call last):\n  File \"/home/azureuser/./python-sample/log2.py\", line 44, in <module>\n    raise ValueError(f\"This is sample error number {i + 1} for logging\")\nValueError: This is sample error number 20 for logging\n"}}

{"timestamp": "2024-07-23 11:46:55,019", "level": "INFO", "message": "End of logging example", "service": "my_python_app", "environment": "development"}

{"timestamp": "2024-07-23 11:47:09,760", "level": "INFO", "message": "This is an informational message", "service": "my_python_app", "environment": "development"}

{"timestamp": "2024-07-23 11:47:09,760", "level": "WARNING", "message": "A warning occurred", "service": "my_python_app", "environment": "development"}

{"timestamp": "2024-07-23 11:47:09,760", "level": "ERROR", "message": "Caught an error: This is sample error number 1 for logging", "service": "my_python_app", "environment": "development", "exception": {"type": "ValueError", "message": "This is sample error number 1 for logging", "traceback": "Traceback (most recent call last):\n  File \"/home/azureuser/./python-sample/log2.py\", line 44, in <module>\n    raise ValueError(f\"This is sample error number {i + 1} for logging\")\nValueError: This is sample error number 1 for logging\n"}}

{"timestamp": "2024-07-23 11:47:09,764", "level": "ERROR", "message": "Caught an error: This is sample error number 2 for logging", "service": "my_python_app", "environment": "development", "exception": {"type": "ValueError", "message": "This is sample error number 2 for logging", "traceback": "Traceback (most recent call last):\n  File \"/home/azureuser/./python-sample/log2.py\", line 44, in <module>\n    raise ValueError(f\"This is sample error number {i + 1} for logging\")\nValueError: This is sample error number 2 for logging\n"}}

{"timestamp": "2024-07-23 11:47:09,764", "level": "ERROR", "message": "Caught an error: This is sample error number 3 for logging", "service": "my_python_app", "environment": "development", "exception": {"type": "ValueError", "message": "This is sample error number 3 for logging", "traceback": "Traceback (most recent call last):\n  File \"/home/azureuser/./python-sample/log2.py\", line 44, in <module>\n    raise ValueError(f\"This is sample error number {i + 1} for logging\")\nValueError: This is sample error number 3 for logging\n"}}

{"timestamp": "2024-07-23 11:47:09,765", "level": "ERROR", "message": "Caught an error: This is sample error number 4 for logging", "service": "my_python_app", "environment": "development", "exception": {"type": "ValueError", "message": "This is sample error number 4 for logging", "traceback": "Traceback (most recent call last):\n  File \"/home/azureuser/./python-sample/log2.py\", line 44, in <module>\n    raise ValueError(f\"This is sample error number {i + 1} for logging\")\nValueError: This is sample error number 4 for logging\n"}}

{"timestamp": "2024-07-23 11:47:09,765", "level": "ERROR", "message": "Caught an error: This is sample error number 5 for logging", "service": "my_python_app", "environment": "development", "exception": {"type": "ValueError", "message": "This is sample error number 5 for logging", "traceback": "Traceback (most recent call last):\n  File \"/home/azureuser/./python-sample/log2.py\", line 44, in <module>\n    raise ValueError(f\"This is sample error number {i + 1} for logging\")\nValueError: This is sample error number 5 for logging\n"}}

{"timestamp": "2024-07-23 11:47:09,765", "level": "ERROR", "message": "Caught an error: This is sample error number 6 for logging", "service": "my_python_app", "environment": "development", "exception": {"type": "ValueError", "message": "This is sample error number 6 for logging", "traceback": "Traceback (most recent call last):\n  File \"/home/azureuser/./python-sample/log2.py\", line 44, in <module>\n    raise ValueError(f\"This is sample error number {i + 1} for logging\")\nValueError: This is sample error number 6 for logging\n"}}

{"timestamp": "2024-07-23 11:47:09,766", "level": "ERROR", "message": "Caught an error: This is sample error number 7 for logging", "service": "my_python_app", "environment": "development", "exception": {"type": "ValueError", "message": "This is sample error number 7 for logging", "traceback": "Traceback (most recent call last):\n  File \"/home/azureuser/./python-sample/log2.py\", line 44, in <module>\n    raise ValueError(f\"This is sample error number {i + 1} for logging\")\nValueError: This is sample error number 7 for logging\n"}}

{"timestamp": "2024-07-23 11:47:09,766", "level": "ERROR", "message": "Caught an error: This is sample error number 8 for logging", "service": "my_python_app", "environment": "development", "exception": {"type": "ValueError", "message": "This is sample error number 8 for logging", "traceback": "Traceback (most recent call last):\n  File \"/home/azureuser/./python-sample/log2.py\", line 44, in <module>\n    raise ValueError(f\"This is sample error number {i + 1} for logging\")\nValueError: This is sample error number 8 for logging\n"}}

{"timestamp": "2024-07-23 11:47:09,766", "level": "ERROR", "message": "Caught an error: This is sample error number 9 for logging", "service": "my_python_app", "environment": "development", "exception": {"type": "ValueError", "message": "This is sample error number 9 for logging", "traceback": "Traceback (most recent call last):\n  File \"/home/azureuser/./python-sample/log2.py\", line 44, in <module>\n    raise ValueError(f\"This is sample error number {i + 1} for logging\")\nValueError: This is sample error number 9 for logging\n"}}

{"timestamp": "2024-07-23 11:47:09,766", "level": "ERROR", "message": "Caught an error: This is sample error number 10 for logging", "service": "my_python_app", "environment": "development", "exception": {"type": "ValueError", "message": "This is sample error number 10 for logging", "traceback": "Traceback (most recent call last):\n  File \"/home/azureuser/./python-sample/log2.py\", line 44, in <module>\n    raise ValueError(f\"This is sample error number {i + 1} for logging\")\nValueError: This is sample error number 10 for logging\n"}}

{"timestamp": "2024-07-23 11:47:09,767", "level": "ERROR", "message": "Caught an error: This is sample error number 11 for logging", "service": "my_python_app", "environment": "development", "exception": {"type": "ValueError", "message": "This is sample error number 11 for logging", "traceback": "Traceback (most recent call last):\n  File \"/home/azureuser/./python-sample/log2.py\", line 44, in <module>\n    raise ValueError(f\"This is sample error number {i + 1} for logging\")\nValueError: This is sample error number 11 for logging\n"}}

{"timestamp": "2024-07-23 11:47:09,767", "level": "ERROR", "message": "Caught an error: This is sample error number 12 for logging", "service": "my_python_app", "environment": "development", "exception": {"type": "ValueError", "message": "This is sample error number 12 for logging", "traceback": "Traceback (most recent call last):\n  File \"/home/azureuser/./python-sample/log2.py\", line 44, in <module>\n    raise ValueError(f\"This is sample error number {i + 1} for logging\")\nValueError: This is sample error number 12 for logging\n"}}

{"timestamp": "2024-07-23 11:47:09,767", "level": "ERROR", "message": "Caught an error: This is sample error number 13 for logging", "service": "my_python_app", "environment": "development", "exception": {"type": "ValueError", "message": "This is sample error number 13 for logging", "traceback": "Traceback (most recent call last):\n  File \"/home/azureuser/./python-sample/log2.py\", line 44, in <module>\n    raise ValueError(f\"This is sample error number {i + 1} for logging\")\nValueError: This is sample error number 13 for logging\n"}}

{"timestamp": "2024-07-23 11:47:09,767", "level": "ERROR", "message": "Caught an error: This is sample error number 14 for logging", "service": "my_python_app", "environment": "development", "exception": {"type": "ValueError", "message": "This is sample error number 14 for logging", "traceback": "Traceback (most recent call last):\n  File \"/home/azureuser/./python-sample/log2.py\", line 44, in <module>\n    raise ValueError(f\"This is sample error number {i + 1} for logging\")\nValueError: This is sample error number 14 for logging\n"}}

{"timestamp": "2024-07-23 11:47:09,767", "level": "ERROR", "message": "Caught an error: This is sample error number 15 for logging", "service": "my_python_app", "environment": "development", "exception": {"type": "ValueError", "message": "This is sample error number 15 for logging", "traceback": "Traceback (most recent call last):\n  File \"/home/azureuser/./python-sample/log2.py\", line 44, in <module>\n    raise ValueError(f\"This is sample error number {i + 1} for logging\")\nValueError: This is sample error number 15 for logging\n"}}

{"timestamp": "2024-07-23 11:47:09,768", "level": "ERROR", "message": "Caught an error: This is sample error number 16 for logging", "service": "my_python_app", "environment": "development", "exception": {"type": "ValueError", "message": "This is sample error number 16 for logging", "traceback": "Traceback (most recent call last):\n  File \"/home/azureuser/./python-sample/log2.py\", line 44, in <module>\n    raise ValueError(f\"This is sample error number {i + 1} for logging\")\nValueError: This is sample error number 16 for logging\n"}}

{"timestamp": "2024-07-23 11:47:09,768", "level": "ERROR", "message": "Caught an error: This is sample error number 17 for logging", "service": "my_python_app", "environment": "development", "exception": {"type": "ValueError", "message": "This is sample error number 17 for logging", "traceback": "Traceback (most recent call last):\n  File \"/home/azureuser/./python-sample/log2.py\", line 44, in <module>\n    raise ValueError(f\"This is sample error number {i + 1} for logging\")\nValueError: This is sample error number 17 for logging\n"}}

{"timestamp": "2024-07-23 11:47:09,768", "level": "ERROR", "message": "Caught an error: This is sample error number 18 for logging", "service": "my_python_app", "environment": "development", "exception": {"type": "ValueError", "message": "This is sample error number 18 for logging", "traceback": "Traceback (most recent call last):\n  File \"/home/azureuser/./python-sample/log2.py\", line 44, in <module>\n    raise ValueError(f\"This is sample error number {i + 1} for logging\")\nValueError: This is sample error number 18 for logging\n"}}

{"timestamp": "2024-07-23 11:47:09,768", "level": "ERROR", "message": "Caught an error: This is sample error number 19 for logging", "service": "my_python_app", "environment": "development", "exception": {"type": "ValueError", "message": "This is sample error number 19 for logging", "traceback": "Traceback (most recent call last):\n  File \"/home/azureuser/./python-sample/log2.py\", line 44, in <module>\n    raise ValueError(f\"This is sample error number {i + 1} for logging\")\nValueError: This is sample error number 19 for logging\n"}}

{"timestamp": "2024-07-23 11:47:09,768", "level": "ERROR", "message": "Caught an error: This is sample error number 20 for logging", "service": "my_python_app", "environment": "development", "exception": {"type": "ValueError", "message": "This is sample error number 20 for logging", "traceback": "Traceback (most recent call last):\n  File \"/home/azureuser/./python-sample/log2.py\", line 44, in <module>\n    raise ValueError(f\"This is sample error number {i + 1} for logging\")\nValueError: This is sample error number 20 for logging\n"}}

{"timestamp": "2024-07-23 11:47:09,769", "level": "INFO", "message": "End of logging example", "service": "my_python_app", "environment": "development"}

{"timestamp": "2024-07-23 11:47:18,431", "level": "INFO", "message": "This is an informational message", "service": "my_python_app", "environment": "development"}

{"timestamp": "2024-07-23 11:47:18,431", "level": "WARNING", "message": "A warning occurred", "service": "my_python_app", "environment": "development"}

{"timestamp": "2024-07-23 11:47:18,431", "level": "ERROR", "message": "Caught an error: This is sample error number 1 for logging", "service": "my_python_app", "environment": "development", "exception": {"type": "ValueError", "message": "This is sample error number 1 for logging", "traceback": "Traceback (most recent call last):\n  File \"/home/azureuser/./python-sample/log2.py\", line 44, in <module>\n    raise ValueError(f\"This is sample error number {i + 1} for logging\")\nValueError: This is sample error number 1 for logging\n"}}

{"timestamp": "2024-07-23 11:47:18,435", "level": "ERROR", "message": "Caught an error: This is sample error number 2 for logging", "service": "my_python_app", "environment": "development", "exception": {"type": "ValueError", "message": "This is sample error number 2 for logging", "traceback": "Traceback (most recent call last):\n  File \"/home/azureuser/./python-sample/log2.py\", line 44, in <module>\n    raise ValueError(f\"This is sample error number {i + 1} for logging\")\nValueError: This is sample error number 2 for logging\n"}}

{"timestamp": "2024-07-23 11:47:18,435", "level": "ERROR", "message": "Caught an error: This is sample error number 3 for logging", "service": "my_python_app", "environment": "development", "exception": {"type": "ValueError", "message": "This is sample error number 3 for logging", "traceback": "Traceback (most recent call last):\n  File \"/home/azureuser/./python-sample/log2.py\", line 44, in <module>\n    raise ValueError(f\"This is sample error number {i + 1} for logging\")\nValueError: This is sample error number 3 for logging\n"}}

{"timestamp": "2024-07-23 11:47:18,435", "level": "ERROR", "message": "Caught an error: This is sample error number 4 for logging", "service": "my_python_app", "environment": "development", "exception": {"type": "ValueError", "message": "This is sample error number 4 for logging", "traceback": "Traceback (most recent call last):\n  File \"/home/azureuser/./python-sample/log2.py\", line 44, in <module>\n    raise ValueError(f\"This is sample error number {i + 1} for logging\")\nValueError: This is sample error number 4 for logging\n"}}

{"timestamp": "2024-07-23 11:47:18,435", "level": "ERROR", "message": "Caught an error: This is sample error number 5 for logging", "service": "my_python_app", "environment": "development", "exception": {"type": "ValueError", "message": "This is sample error number 5 for logging", "traceback": "Traceback (most recent call last):\n  File \"/home/azureuser/./python-sample/log2.py\", line 44, in <module>\n    raise ValueError(f\"This is sample error number {i + 1} for logging\")\nValueError: This is sample error number 5 for logging\n"}}

{"timestamp": "2024-07-23 11:47:18,436", "level": "ERROR", "message": "Caught an error: This is sample error number 6 for logging", "service": "my_python_app", "environment": "development", "exception": {"type": "ValueError", "message": "This is sample error number 6 for logging", "traceback": "Traceback (most recent call last):\n  File \"/home/azureuser/./python-sample/log2.py\", line 44, in <module>\n    raise ValueError(f\"This is sample error number {i + 1} for logging\")\nValueError: This is sample error number 6 for logging\n"}}

{"timestamp": "2024-07-23 11:47:18,436", "level": "ERROR", "message": "Caught an error: This is sample error number 7 for logging", "service": "my_python_app", "environment": "development", "exception": {"type": "ValueError", "message": "This is sample error number 7 for logging", "traceback": "Traceback (most recent call last):\n  File \"/home/azureuser/./python-sample/log2.py\", line 44, in <module>\n    raise ValueError(f\"This is sample error number {i + 1} for logging\")\nValueError: This is sample error number 7 for logging\n"}}

{"timestamp": "2024-07-23 11:47:18,436", "level": "ERROR", "message": "Caught an error: This is sample error number 8 for logging", "service": "my_python_app", "environment": "development", "exception": {"type": "ValueError", "message": "This is sample error number 8 for logging", "traceback": "Traceback (most recent call last):\n  File \"/home/azureuser/./python-sample/log2.py\", line 44, in <module>\n    raise ValueError(f\"This is sample error number {i + 1} for logging\")\nValueError: This is sample error number 8 for logging\n"}}

{"timestamp": "2024-07-23 11:47:18,436", "level": "ERROR", "message": "Caught an error: This is sample error number 9 for logging", "service": "my_python_app", "environment": "development", "exception": {"type": "ValueError", "message": "This is sample error number 9 for logging", "traceback": "Traceback (most recent call last):\n  File \"/home/azureuser/./python-sample/log2.py\", line 44, in <module>\n    raise ValueError(f\"This is sample error number {i + 1} for logging\")\nValueError: This is sample error number 9 for logging\n"}}

{"timestamp": "2024-07-23 11:47:18,436", "level": "ERROR", "message": "Caught an error: This is sample error number 10 for logging", "service": "my_python_app", "environment": "development", "exception": {"type": "ValueError", "message": "This is sample error number 10 for logging", "traceback": "Traceback (most recent call last):\n  File \"/home/azureuser/./python-sample/log2.py\", line 44, in <module>\n    raise ValueError(f\"This is sample error number {i + 1} for logging\")\nValueError: This is sample error number 10 for logging\n"}}

{"timestamp": "2024-07-23 11:47:18,437", "level": "ERROR", "message": "Caught an error: This is sample error number 11 for logging", "service": "my_python_app", "environment": "development", "exception": {"type": "ValueError", "message": "This is sample error number 11 for logging", "traceback": "Traceback (most recent call last):\n  File \"/home/azureuser/./python-sample/log2.py\", line 44, in <module>\n    raise ValueError(f\"This is sample error number {i + 1} for logging\")\nValueError: This is sample error number 11 for logging\n"}}

{"timestamp": "2024-07-23 11:47:18,437", "level": "ERROR", "message": "Caught an error: This is sample error number 12 for logging", "service": "my_python_app", "environment": "development", "exception": {"type": "ValueError", "message": "This is sample error number 12 for logging", "traceback": "Traceback (most recent call last):\n  File \"/home/azureuser/./python-sample/log2.py\", line 44, in <module>\n    raise ValueError(f\"This is sample error number {i + 1} for logging\")\nValueError: This is sample error number 12 for logging\n"}}

{"timestamp": "2024-07-23 11:47:18,437", "level": "ERROR", "message": "Caught an error: This is sample error number 13 for logging", "service": "my_python_app", "environment": "development", "exception": {"type": "ValueError", "message": "This is sample error number 13 for logging", "traceback": "Traceback (most recent call last):\n  File \"/home/azureuser/./python-sample/log2.py\", line 44, in <module>\n    raise ValueError(f\"This is sample error number {i + 1} for logging\")\nValueError: This is sample error number 13 for logging\n"}}

{"timestamp": "2024-07-23 11:47:18,437", "level": "ERROR", "message": "Caught an error: This is sample error number 14 for logging", "service": "my_python_app", "environment": "development", "exception": {"type": "ValueError", "message": "This is sample error number 14 for logging", "traceback": "Traceback (most recent call last):\n  File \"/home/azureuser/./python-sample/log2.py\", line 44, in <module>\n    raise ValueError(f\"This is sample error number {i + 1} for logging\")\nValueError: This is sample error number 14 for logging\n"}}

{"timestamp": "2024-07-23 11:47:18,437", "level": "ERROR", "message": "Caught an error: This is sample error number 15 for logging", "service": "my_python_app", "environment": "development", "exception": {"type": "ValueError", "message": "This is sample error number 15 for logging", "traceback": "Traceback (most recent call last):\n  File \"/home/azureuser/./python-sample/log2.py\", line 44, in <module>\n    raise ValueError(f\"This is sample error number {i + 1} for logging\")\nValueError: This is sample error number 15 for logging\n"}}

{"timestamp": "2024-07-23 11:47:18,438", "level": "ERROR", "message": "Caught an error: This is sample error number 16 for logging", "service": "my_python_app", "environment": "development", "exception": {"type": "ValueError", "message": "This is sample error number 16 for logging", "traceback": "Traceback (most recent call last):\n  File \"/home/azureuser/./python-sample/log2.py\", line 44, in <module>\n    raise ValueError(f\"This is sample error number {i + 1} for logging\")\nValueError: This is sample error number 16 for logging\n"}}

{"timestamp": "2024-07-23 11:47:18,438", "level": "ERROR", "message": "Caught an error: This is sample error number 17 for logging", "service": "my_python_app", "environment": "development", "exception": {"type": "ValueError", "message": "This is sample error number 17 for logging", "traceback": "Traceback (most recent call last):\n  File \"/home/azureuser/./python-sample/log2.py\", line 44, in <module>\n    raise ValueError(f\"This is sample error number {i + 1} for logging\")\nValueError: This is sample error number 17 for logging\n"}}

{"timestamp": "2024-07-23 11:47:18,438", "level": "ERROR", "message": "Caught an error: This is sample error number 18 for logging", "service": "my_python_app", "environment": "development", "exception": {"type": "ValueError", "message": "This is sample error number 18 for logging", "traceback": "Traceback (most recent call last):\n  File \"/home/azureuser/./python-sample/log2.py\", line 44, in <module>\n    raise ValueError(f\"This is sample error number {i + 1} for logging\")\nValueError: This is sample error number 18 for logging\n"}}

{"timestamp": "2024-07-23 11:47:18,438", "level": "ERROR", "message": "Caught an error: This is sample error number 19 for logging", "service": "my_python_app", "environment": "development", "exception": {"type": "ValueError", "message": "This is sample error number 19 for logging", "traceback": "Traceback (most recent call last):\n  File \"/home/azureuser/./python-sample/log2.py\", line 44, in <module>\n    raise ValueError(f\"This is sample error number {i + 1} for logging\")\nValueError: This is sample error number 19 for logging\n"}}

{"timestamp": "2024-07-23 11:47:18,438", "level": "ERROR", "message": "Caught an error: This is sample error number 20 for logging", "service": "my_python_app", "environment": "development", "exception": {"type": "ValueError", "message": "This is sample error number 20 for logging", "traceback": "Traceback (most recent call last):\n  File \"/home/azureuser/./python-sample/log2.py\", line 44, in <module>\n    raise ValueError(f\"This is sample error number {i + 1} for logging\")\nValueError: This is sample error number 20 for logging\n"}}

{"timestamp": "2024-07-23 11:47:18,439", "level": "INFO", "message": "End of logging example", "service": "my_python_app", "environment": "development"}

